Workbook

Sheet Voucher Info
A1: Specimen Info Metadata
A2: Sample ID | B2: Field ID | C2: Museum ID | D2: Collection Code | E2: Institution Storing
A3: KBIMP_01_A1 | B3: CBAY0037 | E3: Centre for Biodiversity Genomics
A4: KBIMP_01_A2 | B4: CBAY0037 | E4: Centre for Biodiversity Genomics
A5: KBIMP_01_A3 | B5: CBAY0037 | E5: Centre for Biodiversity Genomics
A6: KBIMP_01_A4 | B6: CBAY0037 | E6: Centre for Biodiversity Genomics
A7: KBIMP_01_A5 | B7: CBAY0037 | E7: Centre for Biodiversity Genomics
A8: KBIMP_01_A6 | B8: CBAY0037 | E8: Centre for Biodiversity Genomics
A9: KBIMP_01_A7 | B9: CBAY0037 | E9: Centre for Biodiversity Genomics
A10: KBIMP_01_A8 | B10: CBAY0037 | E10: Centre for Biodiversity Genomics
A11: KBIMP_01_A9 | B11: CBAY0037 | E11: Centre for Biodiversity Genomics
A12: KBIMP_01_A10 | B12: CBAY0037 | E12: Centre for Biodiversity Genomics
A13: KBIMP_01_A11 | B13: CBAY0037 | E13: Centre for Biodiversity Genomics
A14: KBIMP_01_A12 | B14: CBAY0037 | E14: Centre for Biodiversity Genomics
... A550: KBIMP-_006_G1 | B550: CBAY0055 | E550: Centre for Biodiversity Genomics
A551: KBIMP-_006_G2
A552: KBIMP-_006_G3
A553: KBIMP-_006_G4
A554: KBIMP-_006_G5
A555: KBIMP-_006_G6
A556: KBIMP-_006_G7
A557: KBIMP-_006_G8
A559: KBIMP-_007_A1 | B559: KGLTK0048 | E559: Centre for Biodiversity Genomics
A560: KBIMP-_007_A2 | B560: KGLTK0048 | E560: Centre for Biodiversity Genomics
A561: KBIMP-_007_A3 | B561: KGLTK0032 | E561: Centre for Biodiversity Genomics
A562: KBIMP-_007_A4 | B562: KGLTK0032 | E562: Centre for Biodiversity Genomics
A563: KBIMP-_007_A5 | B563: KGLTK0032 | E563: Centre for Biodiversity Genomics
A564: KBIMP-_007_A6 | B564: KGLTK0032 | E564: Centre for Biodiversity Genomics
A565: KBIMP-_007_A7 | B565: KGLTK0032 | E565: Centre for Biodiversity Genomics
A566: KBIMP-_007_A8 | B566: KGLTK0032 | E566: Centre for Biodiversity Genomics
A567: KBIMP-_007_A9 | B567: KGLTK0032 | E567: Centre for Biodiversity Genomics
A568: KBIMP-_007_A10 | B568: KGLTK0032 | E568: Centre for Biodiversity Genomics
A569: KBIMP-_007_A11 | B569: KGLTK0015 | E569: Centre for Biodiversity Genomics
A570: KBIMP-_007_A12 | B570: KGLTK0015 | E570: Centre for Biodiversity Genomics
... A653: KBIMP-_007_H11 | B653: KGLTK0019 | E653: Centre for Biodiversity Genomics
A654: KBIMP-_007_H12 | B654: control
A655: KBIMP-_008_A1 | B655: KGLTK0019 | E655: Centre for Biodiversity Genomics
A656: KBIMP-_008_A2 | B656: KGLTK0019 | E656: Centre for Biodiversity Genomics
A657: KBIMP-_008_A3 | B657: KGLTK0019 | E657: Centre for Biodiversity Genomics
A658: KBIMP-_008_A4 | B658: KGLTK0019 | E658: Centre for Biodiversity Genomics
...

Sheet Taxonomy
A1: Taxonomy Metadata | M1: Extended Fields (BOLD 3.1)
A2: Sample ID | B2: Phylum | C2: Class | D2: Order | E2: Family | F2: Subfamily | G2: Tribe | H2: Genus | I2: Species | J2: Subspecies | K2: Identifier | L2: Identifier Email | M2: Identification Method | N2: Taxonomy Notes
A3: =IF(ISBLANK('Voucher Info'!A3),"",'Voucher Info'!A3) -> KBIMP_01_A1 | B3: Arthropoda | C3: Insecta | D3: Diptera | E3: Simuliidae | K3: Olivia Colman/Shauna Dowratzek | L3: sdworatz@uoguelph.ca
A4: =IF(ISBLANK('Voucher Info'!A4),"",'Voucher Info'!A4) -> KBIMP_01_A2 | B4: Arthropoda | C4: Insecta | D4: Diptera | E4: Simuliidae | K4: Olivia Colman/Shauna Dowratzek | L4: sdworatz@uoguelph.ca
A5: =IF(ISBLANK('Voucher Info'!A5),"",'Voucher Info'!A5) -> KBIMP_01_A3 | B5: Arthropoda | C5: Insecta | D5: Diptera | E5: Simuliidae | K5: Olivia Colman/Shauna Dowratzek | L5: sdworatz@uoguelph.ca
A6: =IF(ISBLANK('Voucher Info'!A6),"",'Voucher Info'!A6) -> KBIMP_01_A4 | B6: Arthropoda | C6: Insecta | D6: Diptera | E6: Simuliidae | K6: Olivia Colman/Shauna Dowratzek | L6: sdworatz@uoguelph.ca
A7: =IF(ISBLANK('Voucher Info'!A7),"",'Voucher Info'!A7) -> KBIMP_01_A5 | B7: Arthropoda | C7: Insecta | D7: Diptera | E7: Simuliidae | K7: Olivia Colman/Shauna Dowratzek | L7: sdworatz@uoguelph.ca
A8: =IF(ISBLANK('Voucher Info'!A8),"",'Voucher Info'!A8) -> KBIMP_01_A6 | B8: Arthropoda | C8: Insecta | D8: Diptera | E8: Simuliidae | K8: Olivia Colman/Shauna Dowratzek | L8: sdworatz@uoguelph.ca
A9: =IF(ISBLANK('Voucher Info'!A9),"",'Voucher Info'!A9) -> KBIMP_01_A7 | B9: Arthropoda | C9: Insecta | D9: Diptera | E9: Simuliidae | K9: Olivia Colman/Shauna Dowratzek | L9: sdworatz@uoguelph.ca
A10: =IF(ISBLANK('Voucher Info'!A10),"",'Voucher Info'!A10) -> KBIMP_01_A8 | B10: Arthropoda | C10: Insecta | D10: Diptera | E10: Simuliidae | K10: Olivia Colman/Shauna Dowratzek | L10: sdworatz@uoguelph.ca
A11: =IF(ISBLANK('Voucher Info'!A11),"",'Voucher Info'!A11) -> KBIMP_01_A9 | B11: Arthropoda | C11: Insecta | D11: Diptera | E11: Simuliidae | K11: Olivia Colman/Shauna Dowratzek | L11: sdworatz@uoguelph.ca
A12: =IF(ISBLANK('Voucher Info'!A12),"",'Voucher Info'!A12) -> KBIMP_01_A10 | B12: Arthropoda | C12: Insecta | D12: Diptera | E12: Simuliidae | K12: Olivia Colman/Shauna Dowratzek | L12: sdworatz@uoguelph.ca
A13: =IF(ISBLANK('Voucher Info'!A13),"",'Voucher Info'!A13) -> KBIMP_01_A11 | B13: Arthropoda | C13: Insecta | D13: Diptera | E13: Simuliidae | K13: Olivia Colman/Shauna Dowratzek | L13: sdworatz@uoguelph.ca
A14: =IF(ISBLANK('Voucher Info'!A14),"",'Voucher Info'!A14) -> KBIMP_01_A12 | B14: Arthropoda | C14: Insecta | D14: Diptera | E14: Simuliidae | K14: Olivia Colman/Shauna Dowratzek | L14: sdworatz@uoguelph.ca
... A550: =IF(ISBLANK('Voucher Info'!A550),"",'Voucher Info'!A550) -> KBIMP-_006_G1 | B550: Arthropoda | C550: Insecta | D550: Diptera | E550: Culicidae | K550: Olivia Colman/Shauna Dowratzek | L550: sdworatz@uoguelph.ca
A551: =IF(ISBLANK('Voucher Info'!A551),"",'Voucher Info'!A551) -> KBIMP-_006_G2
A552: =IF(ISBLANK('Voucher Info'!A552),"",'Voucher Info'!A552) -> KBIMP-_006_G3
A553: =IF(ISBLANK('Voucher Info'!A553),"",'Voucher Info'!A553) -> KBIMP-_006_G4
A554: =IF(ISBLANK('Voucher Info'!A554),"",'Voucher Info'!A554) -> KBIMP-_006_G5
A555: =IF(ISBLANK('Voucher Info'!A555),"",'Voucher Info'!A555) -> KBIMP-_006_G6
A556: =IF(ISBLANK('Voucher Info'!A556),"",'Voucher Info'!A556) -> KBIMP-_006_G7
A557: =IF(ISBLANK('Voucher Info'!A557),"",'Voucher Info'!A557) -> KBIMP-_006_G8
A558: =IF(ISBLANK('Voucher Info'!A559),"",'Voucher Info'!A559) -> KBIMP-_007_A1 | B558: Arthropoda | C558: Insecta | D558: Diptera | E558: Simuliidae | K558: Shauna | L558: sdworatz@uoguelph.ca
A559: =IF(ISBLANK('Voucher Info'!A560),"",'Voucher Info'!A560) -> KBIMP-_007_A2 | B559: Arthropoda | C559: Insecta | D559: Diptera | E559: Simuliidae | K559: Shauna | L559: sdworatz@uoguelph.ca
A560: =IF(ISBLANK('Voucher Info'!A561),"",'Voucher Info'!A561) -> KBIMP-_007_A3 | B560: Arthropoda | C560: Insecta | D560: Diptera | E560: Culicidae | K560: Shauna | L560: sdworatz@uoguelph.ca
A561: =IF(ISBLANK('Voucher Info'!A562),"",'Voucher Info'!A562) -> KBIMP-_007_A4 | B561: Arthropoda | C561: Insecta | D561: Diptera | E561: Culicidae | K561: Shauna | L561: sdworatz@uoguelph.ca
A562: =IF(ISBLANK('Voucher Info'!A563),"",'Voucher Info'!A563) -> KBIMP-_007_A5 | B562: Arthropoda | C562: Insecta | D562: Diptera | E562: Culicidae | K562: Shauna | L562: sdworatz@uoguelph.ca
A563: =IF(ISBLANK('Voucher Info'!A564),"",'Voucher Info'!A564) -> KBIMP-_007_A6 | B563: Arthropoda | C563: Insecta | D563: Diptera | E563: Simuliidae | K563: Shauna | L563: sdworatz@uoguelph.ca
A564: =IF(ISBLANK('Voucher Info'!A565),"",'Voucher Info'!A565) -> KBIMP-_007_A7 | B564: Arthropoda | C564: Insecta | D564: Diptera | E564: Simuliidae | K564: Shauna | L564: sdworatz@uoguelph.ca
A565: =IF(ISBLANK('Voucher Info'!A566),"",'Voucher Info'!A566) -> KBIMP-_007_A8 | B565: Arthropoda | C565: Insecta | D565: Diptera | E565: Simuliidae | K565: Shauna | L565: sdworatz@uoguelph.ca
A566: =IF(ISBLANK('Voucher Info'!A567),"",'Voucher Info'!A567) -> KBIMP-_007_A9 | B566: Arthropoda | C566: Insecta | D566: Diptera | E566: Simuliidae | K566: Shauna | L566: sdworatz@uoguelph.ca
A567: =IF(ISBLANK('Voucher Info'!A568),"",'Voucher Info'!A568) -> KBIMP-_007_A10 | B567: Arthropoda | C567: Insecta | D567: Diptera | E567: Simuliidae | K567: Shauna | L567: sdworatz@uoguelph.ca
A568: =IF(ISBLANK('Voucher Info'!A569),"",'Voucher Info'!A569) -> KBIMP-_007_A11 | B568: Arthropoda | C568: Insecta | D568: Diptera | E568: Culicidae | K568: Shauna | L568: sdworatz@uoguelph.ca
A569: =IF(ISBLANK('Voucher Info'!A570),"",'Voucher Info'!A570) -> KBIMP-_007_A12 | B569: Arthropoda | C569: Insecta | D569: Diptera | E569: Culicidae | K569: Shauna | L569: sdworatz@uoguelph.ca
... A594: =IF(ISBLANK('Voucher Info'!A595),"",'Voucher Info'!A595) -> KBIMP-_007_D1 | B594: Arthropoda | C594: Insecta | D594: Diptera | E594: Simuliidae | K594: Shauna | L594: sdworatz@uoguelph.ca
A595: KBIMP-_007_D2 | B595: Arthropoda | C595: Insecta | D595: Diptera | E595: Culicidae | K595: Shauna | L595: sdworatz@uoguelph.ca
A596: KBIMP-_007_D3 | B596: Arthropoda | C596: Insecta | D596: Diptera | E596: Culicidae | K596: Shauna | L596: sdworatz@uoguelph.ca
A597: KBIMP-_007_D4 | B597: Arthropoda | C597: Insecta | D597: Diptera | E597: Simuliidae | K597: Shauna | L597: sdworatz@uoguelph.ca
A598: KBIMP-_007_D5 | B598: Arthropoda | C598: Insecta | D598: Diptera | E598: Simuliidae | K598: Shauna | L598: sdworatz@uoguelph.ca
A599: KBIMP-_007_D6 | B599: Arthropoda | C599: Insecta | D599: Diptera | E599: Simuliidae | K599: Shauna | L599: sdworatz@uoguelph.ca
...

Sheet Specimen Details
A1: Specimen Details Metadata | G1: Specimen Details Metadata Extended Fields (BOLD 3.1)
A2: Sample ID | B2: Sex | C2: Reproduction | D2: Life Stage | E2: Extra Info | F2: Notes | G2: Voucher Status | H2: Tissue Descriptor | I2: External URLs | J2: Associated Taxa | K2: Associated Specimens
A3: =IF(ISBLANK('Voucher Info'!A3),"",'Voucher Info'!A3) -> KBIMP_01_A1 | D3: Larvae
A4: =IF(ISBLANK('Voucher Info'!A4),"",'Voucher Info'!A4) -> KBIMP_01_A2 | D4: Larvae
A5: =IF(ISBLANK('Voucher Info'!A5),"",'Voucher Info'!A5) -> KBIMP_01_A3 | D5: Larvae
A6: =IF(ISBLANK('Voucher Info'!A6),"",'Voucher Info'!A6) -> KBIMP_01_A4 | D6: Larvae
A7: =IF(ISBLANK('Voucher Info'!A7),"",'Voucher Info'!A7) -> KBIMP_01_A5 | D7: Larvae
A8: =IF(ISBLANK('Voucher Info'!A8),"",'Voucher Info'!A8) -> KBIMP_01_A6 | D8: Larvae
A9: =IF(ISBLANK('Voucher Info'!A9),"",'Voucher Info'!A9) -> KBIMP_01_A7 | D9: Larvae
A10: =IF(ISBLANK('Voucher Info'!A10),"",'Voucher Info'!A10) -> KBIMP_01_A8 | D10: Larvae
A11: =IF(ISBLANK('Voucher Info'!A11),"",'Voucher Info'!A11) -> KBIMP_01_A9 | D11: Larvae
A12: =IF(ISBLANK('Voucher Info'!A12),"",'Voucher Info'!A12) -> KBIMP_01_A10 | D12: Larvae
A13: =IF(ISBLANK('Voucher Info'!A13),"",'Voucher Info'!A13) -> KBIMP_01_A11 | D13: Larvae
A14: =IF(ISBLANK('Voucher Info'!A14),"",'Voucher Info'!A14) -> KBIMP_01_A12 | D14: Larvae
... A550: =IF(ISBLANK('Voucher Info'!A550),"",'Voucher Info'!A550) -> KBIMP-_006_G1 | D550: Adult
A558: =IF(ISBLANK('Voucher Info'!A559),"",'Voucher Info'!A559) -> KBIMP-_007_A1 | D558: Adult
A559: =IF(ISBLANK('Voucher Info'!A560),"",'Voucher Info'!A560) -> KBIMP-_007_A2 | D559: Adult
A560: =IF(ISBLANK('Voucher Info'!A561),"",'Voucher Info'!A561) -> KBIMP-_007_A3 | D560: Adult
A561: =IF(ISBLANK('Voucher Info'!A562),"",'Voucher Info'!A562) -> KBIMP-_007_A4 | D561: Adult
A562: =IF(ISBLANK('Voucher Info'!A563),"",'Voucher Info'!A563) -> KBIMP-_007_A5 | D562: Adult
A563: =IF(ISBLANK('Voucher Info'!A564),"",'Voucher Info'!A564) -> KBIMP-_007_A6 | D563: Adult
A564: =IF(ISBLANK('Voucher Info'!A565),"",'Voucher Info'!A565) -> KBIMP-_007_A7 | D564: Adult
A565: =IF(ISBLANK('Voucher Info'!A566),"",'Voucher Info'!A566) -> KBIMP-_007_A8 | D565: Adult
A566: =IF(ISBLANK('Voucher Info'!A567),"",'Voucher Info'!A567) -> KBIMP-_007_A9 | D566: Adult
A567: =IF(ISBLANK('Voucher Info'!A568),"",'Voucher Info'!A568) -> KBIMP-_007_A10 | D567: Adult
A568: =IF(ISBLANK('Voucher Info'!A569),"",'Voucher Info'!A569) -> KBIMP-_007_A11 | D568: Adult
A569: =IF(ISBLANK('Voucher Info'!A570),"",'Voucher Info'!A570) -> KBIMP-_007_A12 | D569: Adult
... A594: =IF(ISBLANK('Voucher Info'!A595),"",'Voucher Info'!A595) -> KBIMP-_007_D1 | D594: Adult
A595: KBIMP-_007_D2 | D595: Adult
A596: KBIMP-_007_D3 | D596: Adult
A597: KBIMP-_007_D4 | D597: Adult
A598: KBIMP-_007_D5 | D598: Adult
A599: KBIMP-_007_D6 | D599: Adult
A600: KBIMP-_007_D7 | D600: Adult
A601: KBIMP-_007_D8 | D601: Adult
A602: KBIMP-_007_D9 | D602: Adult
A603: =IF(ISBLANK('Voucher Info'!A605),"",'Voucher Info'!A605) -> KBIMP-_007_D11 | D603: Adult
A604: KBIMP-_007_D10 | D604: Adult
A605: KBIMP-_007_D11 | D605: Adult
A606: KBIMP-_007_D12 | D606: Adult
...

Sheet Collection Data
A1: Collection Info Metadata | L1: Collection Info Metadata Extended Fields (BOLD 3.1)
A2: Sample ID | B2: Collectors | C2: Collection Date | D2: Country/Ocean | E2: State/Province | F2: Region | G2: Sector | H2: Exact Site | I2: Lat | J2: Lon | K2: Elev | L2: Depth | M2: Elevation Precision | N2: Depth Precision | O2: GPS Source | P2: Coordinate Accuracy | Q2: Event Time | R2: Collection Date Accuracy | S2: Habitat | T2: Sampling Protocol | U2: Collection Notes | V2: Site Code | W2: Field ID
A3: =IF(ISBLANK('Voucher Info'!A3),"",'Voucher Info'!A3) -> KBIMP_01_A1 | B3: D. Nowosad | C3: July 25 2024 | D3: Canada | E3: Nunavut | F3: Kitikmeot | H3: DEW Line Rd | I3: 69.158318 | J3: 105.19028 | K3: 24m | T3: Dipnet | W3: CBAY0037
A4: =IF(ISBLANK('Voucher Info'!A4),"",'Voucher Info'!A4) -> KBIMP_01_A2 | B4: D. Nowosad | C4: July 25 2024 | D4: Canada | E4: Nunavut | F4: Kitikmeot | H4: DEW Line Rd | I4: 69.158318 | J4: 105.19028 | K4: 24m | T4: Dipnet | W4: CBAY0037
A5: =IF(ISBLANK('Voucher Info'!A5),"",'Voucher Info'!A5) -> KBIMP_01_A3 | B5: D. Nowosad | C5: July 25 2024 | D5: Canada | E5: Nunavut | F5: Kitikmeot | H5: DEW Line Rd | I5: 69.158318 | J5: 105.19028 | K5: 24m | T5: Dipnet | W5: CBAY0037
A6: =IF(ISBLANK('Voucher Info'!A6),"",'Voucher Info'!A6) -> KBIMP_01_A4 | B6: D. Nowosad | C6: July 25 2024 | D6: Canada | E6: Nunavut | F6: Kitikmeot | H6: DEW Line Rd | I6: 69.158318 | J6: 105.19028 | K6: 24m | T6: Dipnet | W6: CBAY0037
A7: =IF(ISBLANK('Voucher Info'!A7),"",'Voucher Info'!A7) -> KBIMP_01_A5 | B7: D. Nowosad | C7: July 25 2024 | D7: Canada | E7: Nunavut | F7: Kitikmeot | H7: DEW Line Rd | I7: 69.158318 | J7: 105.19028 | K7: 24m | T7: Dipnet | W7: CBAY0037
A8: =IF(ISBLANK('Voucher Info'!A8),"",'Voucher Info'!A8) -> KBIMP_01_A6 | B8: D. Nowosad | C8: July 25 2024 | D8: Canada | E8: Nunavut | F8: Kitikmeot | H8: DEW Line Rd | I8: 69.158318 | J8: 105.19028 | K8: 24m | T8: Dipnet | W8: CBAY0037
A9: =IF(ISBLANK('Voucher Info'!A9),"",'Voucher Info'!A9) -> KBIMP_01_A7 | B9: D. Nowosad | C9: July 25 2024 | D9: Canada | E9: Nunavut | F9: Kitikmeot | H9: DEW Line Rd | I9: 69.158318 | J9: 105.19028 | K9: 24m | T9: Dipnet | W9: CBAY0037
A10: =IF(ISBLANK('Voucher Info'!A10),"",'Voucher Info'!A10) -> KBIMP_01_A8 | B10: D. Nowosad | C10: July 25 2024 | D10: Canada | E10: Nunavut | F10: Kitikmeot | H10: DEW Line Rd | I10: 69.158318 | J10: 105.19028 | K10: 24m | T10: Dipnet | W10: CBAY0037
A11: =IF(ISBLANK('Voucher Info'!A11),"",'Voucher Info'!A11) -> KBIMP_01_A9 | B11: D. Nowosad | C11: July 25 2024 | D11: Canada | E11: Nunavut | F11: Kitikmeot | H11: DEW Line Rd | I11: 69.158318 | J11: 105.19028 | K11: 24m | T11: Dipnet | W11: CBAY0037
A12: =IF(ISBLANK('Voucher Info'!A12),"",'Voucher Info'!A12) -> KBIMP_01_A10 | B12: D. Nowosad | C12: July 25 2024 | D12: Canada | E12: Nunavut | F12: Kitikmeot | H12: DEW Line Rd | I12: 69.158318 | J12: 105.19028 | K12: 24m | T12: Dipnet | W12: CBAY0037
A13: =IF(ISBLANK('Voucher Info'!A13),"",'Voucher Info'!A13) -> KBIMP_01_A11 | B13: D. Nowosad | C13: July 25 2024 | D13: Canada | E13: Nunavut | F13: Kitikmeot | H13: DEW Line Rd | I13: 69.158318 | J13: 105.19028 | K13: 24m | T13: Dipnet | W13: CBAY0037
A14: =IF(ISBLANK('Voucher Info'!A14),"",'Voucher Info'!A14) -> KBIMP_01_A12 | B14: D. Nowosad | C14: July 25 2024 | D14: Canada | E14: Nunavut | F14: Kitikmeot | H14: DEW Line Rd | I14: 69.158318 | J14: 105.19028 | K14: 24m | T14: Dipnet | W14: CBAY0037
... A87: =IF(ISBLANK('Voucher Info'!A87),"",'Voucher Info'!A87) -> KBIMP_01_H1 | B87: D. Nowosad | C87: July 21 2024 | D87: Canada | E87: Nunavut | F87: Kitikmeot | H87: Stream between 1st lake and Grenier | I87: 69.20555 | J87: -104.78194 | K87: 10m | T87: Dipnet | W87: CBAY0020
A88: =IF(ISBLANK('Voucher Info'!A88),"",'Voucher Info'!A88) -> KBIMP_01_H2 | B88: D. Nowosad | C88: July 24 2024 | D88: Canada | E88: Nunavut | F88: Kitikmeot | H88: Freshwater river by picnic area | I88: 69.132486 | J88: -104.9887 | T88: Dipnet | W88: CBAY0029
A89: =IF(ISBLANK('Voucher Info'!A89),"",'Voucher Info'!A89) -> KBIMP_01_H3 | B89: D. Nowosad | C89: July 24 2024 | D89: Canada | E89: Nunavut | F89: Kitikmeot | H89: Freshwater river by picnic area | I89: 69.132486 | J89: -104.9887 | T89: Dipnet | W89: CBAY0029
A90: =IF(ISBLANK('Voucher Info'!A90),"",'Voucher Info'!A90) -> KBIMP_01_H4 | B90: D. Nowosad | C90: July 24 2024 | D90: Canada | E90: Nunavut | F90: Kitikmeot | H90: Freshwater river by picnic area | I90: 69.132486 | J90: -104.9887 | T90: Dipnet | W90: CBAY0029
A91: =IF(ISBLANK('Voucher Info'!A91),"",'Voucher Info'!A91) -> KBIMP_01_H5 | B91: D. Nowosad | C91: July 24 2024 | D91: Canada | E91: Nunavut | F91: Kitikmeot | H91: Freshwater river by picnic area | I91: 69.132486 | J91: -104.9887 | T91: Dipnet | W91: CBAY0029
A92: =IF(ISBLANK('Voucher Info'!A92),"",'Voucher Info'!A92) -> KBIMP_01_H6 | B92: D. Nowosad | C92: July 24 2024 | D92: Canada | E92: Nunavut | F92: Kitikmeot | H92: Freshwater river by picnic area | I92: 69.132486 | J92: -104.9887 | T92: Dipnet | W92: CBAY0029
A93: =IF(ISBLANK('Voucher Info'!A93),"",'Voucher Info'!A93) -> KBIMP_01_H7 | B93: D. Nowosad | C93: July 24 2024 | D93: Canada | E93: Nunavut | F93: Kitikmeot | H93: Freshwater river by picnic area | I93: 69.132486 | J93: -104.9887 | T93: Dipnet | W93: CBAY0029
A94: =IF(ISBLANK('Voucher Info'!A94),"",'Voucher Info'!A94) -> KBIMP_01_H8 | B94: D. Nowosad | C94: July 24 2024 | D94: Canada | E94: Nunavut | F94: Kitikmeot | H94: Freshwater river by picnic area | I94: 69.132486 | J94: -104.9887 | T94: Dipnet | W94: CBAY0029
A95: =IF(ISBLANK('Voucher Info'!A95),"",'Voucher Info'!A95) -> KBIMP_01_H9 | B95: D. Nowosad | C95: July 24 2024 | D95: Canada | E95: Nunavut | F95: Kitikmeot | H95: Freshwater river by picnic area | I95: 69.132486 | J95: -104.9887 | T95: Dipnet | W95: CBAY0029
A96: =IF(ISBLANK('Voucher Info'!A96),"",'Voucher Info'!A96) -> KBIMP_01_H10 | B96: D. Nowosad | C96: July 24 2024 | D96: Canada | E96: Nunavut | F96: Kitikmeot | H96: Freshwater river by picnic area | I96: 69.132486 | J96: -104.9887 | T96: Dipnet | W96: CBAY0029
A97: =IF(ISBLANK('Voucher Info'!A97),"",'Voucher Info'!A97) -> KBIMP_01_H11 | B97: D. Nowosad | C97: July 24 2024 | D97: Canada | E97: Nunavut | F97: Kitikmeot | H97: Freshwater river by picnic area | I97: 69.132486 | J97: -104.9887 | T97: Dipnet | W97: CBAY0029
A98: =IF(ISBLANK('Voucher Info'!A98),"",'Voucher Info'!A98) -> KBIMP_002_A1 | B98: D. Nowosad | C98: July 28 2024 | D98: Canada | E98: Nunavut | F98: Kitikmeot | H98: Freshwater river | I98: 69.112595 | J98: -105.01024 | T98: Dipnet | W98: CBAY0026
A99: =IF(ISBLANK('Voucher Info'!A99),"",'Voucher Info'!A99) -> KBIMP_002_A2 | B99: D. Nowosad | C99: July 28 2024 | D99: Canada | E99: Nunavut | F99: Kitikmeot | H99: Freshwater river | I99: 69.112595 | J99: -105.01024 | T99: Dipnet | W99: CBAY0026
... A109: =IF(ISBLANK('Voucher Info'!A109),"",'Voucher Info'!A109) -> KBIMP_002_A12 | B109: D. Nowosad | C109: July 24 2024 | D109: Canada | E109: Nunavut | F109: Kitikmeot | H109: Freshwater river by picnic area | I109: 69.132438 | J109: -104.98883 | T109: Surber net | W109: CBAY0030
A110: =IF(ISBLANK('Voucher Info'!A110),"",'Voucher Info'!A110) -> KBIMP_002_B1 | B110: D. Nowosad | C110: July 21 2024 | D110: Canada | E110: Nunavut | F110: Kitikmeot | I110: 69.204444 | J110: -104.77389 | T110: Surber net | W110: CBAY0021
A111: =IF(ISBLANK('Voucher Info'!A111),"",'Voucher Info'!A111) -> KBIMP_002_B2 | B111: D. Nowosad | C111: July 24 2024 | D111: Canada | E111: Nunavut | F111: Kitikmeot | H111: Freshwater river by picnic area | I111: 69.132438 | J111: -104.98883 | T111: Surber net | W111: CBAY0030
A112: =IF(ISBLANK('Voucher Info'!A112),"",'Voucher Info'!A112) -> KBIMP_002_B3 | B112: D. Nowosad | C112: July 24 2024 | D112: Canada | E112: Nunavut | F112: Kitikmeot | H112: Freshwater river by picnic area | I112: 69.132438 | J112: -104.98883 | T112: Surber net | W112: CBAY0030
A113: =IF(ISBLANK('Voucher Info'!A113),"",'Voucher Info'!A113) -> KBIMP_002_B4 | B113: D. Nowosad | C113: July 24 2024 | D113: Canada | E113: Nunavut | F113: Kitikmeot | H113: Freshwater river by picnic area | I113: 69.132438 | J113: -104.98883 | T113: Surber net | W113: CBAY0030
A114: =IF(ISBLANK('Voucher Info'!A114),"",'Voucher Info'!A114) -> KBIMP_002_B5 | B114: D. Nowosad | C114: July 24 2024 | D114: Canada | E114: Nunavut | F114: Kitikmeot | H114: Freshwater river by picnic area | I114: 69.132438 | J114: -104.98883 | T114: Surber net | W114: CBAY0030
A115: =IF(ISBLANK('Voucher Info'!A115),"",'Voucher Info'!A115) -> KBIMP_002_B6 | B115: D. Nowosad | C115: July 24 2024 | D115: Canada | E115: Nunavut | F115: Kitikmeot | H115: Freshwater river by picnic area | I115: 69.132438 | J115: -104.98883 | T115: Surber net | W115: CBAY0030
A116: =IF(ISBLANK('Voucher Info'!A116),"",'Voucher Info'!A116) -> KBIMP_002_B7 | B116: D. Nowosad | C116: July 24 2024 | D116: Canada | E116: Nunavut | F116: Kitikmeot | H116: Freshwater river by picnic area | I116: 69.132438 | J116: -104.98883 | T116: Surber net | W116: CBAY0030
A117: =IF(ISBLANK('Voucher Info'!A117),"",'Voucher Info'!A117) -> KBIMP_002_B8 | B117: D. Nowosad | C117: July 24 2024 | D117: Canada | E117: Nunavut | F117: Kitikmeot | H117: Freshwater river by picnic area | I117: 69.132438 | J117: -104.98883 | T117: Surber net | W117: CBAY0030
A118: =IF(ISBLANK('Voucher Info'!A118),"",'Voucher Info'!A118) -> KBIMP_002_B9 | B118: D. Nowosad | C118: July 24 2024 | D118: Canada | E118: Nunavut | F118: Kitikmeot | H118: Freshwater river by picnic area | I118: 69.132438 | J118: -104.98883 | T118: Surber net | W118: CBAY0030
A119: =IF(ISBLANK('Voucher Info'!A119),"",'Voucher Info'!A119) -> KBIMP_002_B10 | B119: D. Nowosad | C119: July 24 2024 | D119: Canada | E119: Nunavut | F119: Kitikmeot | H119: Freshwater river by picnic area | I119: 69.132438 | J119: -104.98883 | T119: Surber net | W119: CBAY0030
A120: =IF(ISBLANK('Voucher Info'!A120),"",'Voucher Info'!A120) -> KBIMP_002_B11 | B120: D. Nowosad | C120: July 24 2024 | D120: Canada | E120: Nunavut | F120: Kitikmeot | H120: Freshwater river by picnic area | I120: 69.132438 | J120: -104.98883 | T120: Surber net | W120: CBAY0030
A121: =IF(ISBLANK('Voucher Info'!A121),"",'Voucher Info'!A121) -> KBIMP_002_B12 | B121: Cassia | C121: June 7 2024 | D121: Canada | E121: Nunavut | F121: Kitikmeot | H121: Kitigak River - Site 1 | T121: Surber net | W121: CBAY0017
...
